{
	"id": "CVE-2021-25288",
	"vulnerabilities": [
		{
			"id": "CVE-2021-25288",
			"description": "An issue was discovered in Pillow before 8.2.0. There is an out-of-bounds read in J2kDecode, in j2ku_gray_i.",
			"severity": [
				{
					"type": "cvss_v31",
					"source": "security.alpinelinux.org",
					"cvss_v31": {
						"vector": "CVSS:3.1/AV:N/AC:L/PR:N/UI:N/S:U/C:H/I:N/A:H",
						"base_score": 9.1,
						"base_severity": "CRITICAL",
						"temporal_score": 9.1,
						"temporal_severity": "CRITICAL",
						"environmental_score": 9.1,
						"environmental_severity": "CRITICAL"
					}
				}
			],
			"references": [
				{
					"source": "security.alpinelinux.org",
					"url": "https://security.alpinelinux.org/vuln/CVE-2021-25288"
				},
				{
					"source": "security.alpinelinux.org",
					"url": "https://pillow.readthedocs.io/en/stable/releasenotes/8.2.0.html#cve-2021-25287-cve-2021-25288-fix-oob-read-in-jpeg2kdecode"
				},
				{
					"source": "security.alpinelinux.org",
					"url": "https://security.gentoo.org/glsa/202107-33"
				},
				{
					"source": "security.alpinelinux.org",
					"url": "https://github.com/python-pillow/Pillow/pull/5377#issuecomment-833821470"
				},
				{
					"source": "security.alpinelinux.org",
					"url": "https://lists.fedoraproject.org/archives/list/package-announce%40lists.fedoraproject.org/message/MQHA5HAIBOYI3R6HDWCLAGFTIQP767FL/"
				}
			],
			"published": "2021-06-02T16:15:08Z",
			"modified": "2023-12-06T01:00:57.46923Z"
		}
	],
	"detection": [
		{
			"ecosystem": "alpine:3.14",
			"vulnerable": true,
			"package": {
				"name": "py3-pillow"
			},
			"affected": {
				"type": "apk",
				"range": [
					{
						"lt": "8.2.0-r0"
					}
				],
				"fixed": [
					"8.2.0-r0"
				]
			}
		},
		{
			"ecosystem": "alpine:3.15",
			"vulnerable": true,
			"package": {
				"name": "py3-pillow"
			},
			"affected": {
				"type": "apk",
				"range": [
					{
						"lt": "8.2.0-r0"
					}
				],
				"fixed": [
					"8.2.0-r0"
				]
			}
		}
	],
	"data_source": "alpine-osv"
}
